Workbook

Sheet Équipe 17
A1: =[1]Maître!$A$1 -> GTI525 — Technologies de développement Internet
A2: =[1]Maître!$A$2 -> Grille d'évaluation — Phase 1 — Conception du front-end
A3: =[1]Maître!$A$3 -> Application « MTL Vélo » — Parcours classique ou augmenté par l'IA
A4: ⚠ PROPOSITION D'ÉVALUATION — à valider par le chargé(e) de laboratoire. Les notes et pénalités proposées doivent être vérifiées avant d'être communiquées à l'équipe.
A6: Identification
A7: Équipe n° | C7: 17 | D7: Date | F7: 2026-06-17
A8: Section | C8: 01 | D8: Chargé(e) de laboratoire | F8: Marcos Dias de Assunção
A9: Membre 1 | C9: Omar Khudhair | D9: Membre 2 | F9: Christian Junior Djomga
A10: Membre 3 | D10: Lien dépôt Git | F10: https://github.com/ramo2k/gti525-labo
A11: Tag de soumission | C11: phase1-submission | D11: SHA du commit | F11: 7c8b961ebb72b0ced7cea06d0226a3495b543613
A13: Parcours déclaré par l'équipe
A14: ☑ | B14: Parcours augmenté par l'IA | C14: (évalué via PROMPTS.md + DEMARCHE.md)
A15: ☐ | B15: Parcours classique sans IA | C15: (évalué via DEMARCHE.md uniquement)
A16: ☐ | B16: Parcours non déclaré | C16: (absence de DEMARCHE.md — voir la pénalité correspondante)
A18: Vérifications préalables
A19: Pour chaque ligne, attribuer une note entre 0 et le maximum et inscrire un commentaire. Les notes proposées s'appuient sur des éléments observables du dépôt ; les critères non évaluables sans la démo ou le rapport restent vides.
A20: Vérification du tag : git fetch --tags && git rev-parse phase1-submission. Si le tag est absent, divergent du SHA déposé ou créé après la date limite, appliquer la pénalité de soumission et évaluer la version pointée par le tag.
A22: =[1]Maître!$A$6 -> 1. Démonstration en direct — 25 points
A23: # | B23: Critère | C23: Description | D23: Max | E23: Note | F23: Commentaires
A24: =[1]Maître!$A$8 -> D1 | B24: =[1]Maître!$B$8 -> Navigation et structure | C24: =[1]Maître!$C$8 -> Toutes les pages prévues sont présentes, la navigation fonctionne, l'état actif et l'état :hover sont visibles. | D24: =[1]Maître!$D$8 -> 5 | E24: 3 | F24: Il manque quelques éléments dans Home. À propos pas implémentée.
A25: =[1]Maître!$A$9 -> D2 | B25: =[1]Maître!$B$9 -> Affichage des données | C25: =[1]Maître!$C$9 -> Les compteurs et points d'intérêt sont chargés depuis les fichiers et correctement affichés. | D25: =[1]Maître!$D$9 -> 5 | E25: 5
A26: =[1]Maître!$A$10 -> D3 | B26: =[1]Maître!$B$10 -> Tri, recherche, filtres | C26: =[1]Maître!$C$10 -> Le tri par colonne, la recherche par nom et le filtre par arrondissement fonctionnent en direct. | D26: =[1]Maître!$D$10 -> 5 | E26: 5
A27: =[1]Maître!$A$11 -> D4 | B27: =[1]Maître!$B$11 -> Thème et accessibilité | C27: =[1]Maître!$C$11 -> Le thème respecte les contrastes WCAG ; les couleurs sont cohérentes ; la mise en page reste lisible. | D27: =[1]Maître!$D$11 -> 5 | E27: 5
A28: =[1]Maître!$A$12 -> D5 | B28: =[1]Maître!$B$12 -> Maîtrise du code | C28: =[1]Maître!$C$12 -> Chaque membre explique son code et défend ses choix techniques. | D28: =[1]Maître!$D$12 -> 5 | E28: 5
A29: Sous-total — démonstration | D29: =[1]Maître!$D$13 -> 25 | E29: =SUM(E24:E28) -> 23
A31: =[1]Maître!$A$15 -> 2. Code et dépôt Git — 35 points
A32: # | B32: Critère | C32: Description | D32: Max | E32: Note | F32: Commentaires
A33: =[1]Maître!$A$17 -> C1 | B33: =[1]Maître!$B$17 -> Structure du code | C33: =[1]Maître!$C$17 -> HTML sémantique, séparation HTML / CSS / JS, modules JS organisés. | D33: =[1]Maître!$D$17 -> 8 | E33: 8 | F33: header/nav/main/footer ✓, NavLink actif ✓, focus:ring sur inputs ✓. Mais : lang='en' dans index.html (app entièrement en français — WCAG 3.1.1), labels sans htmlFor ni id sur tous les champs de filtre (Statistiques.jsx:138, POI.jsx:86), hamburger <button> sans aria-label/aria-expanded/aria-controls (Navbar.jsx:44), tri via onClick sur <th> au lieu d'un <button> (DataTable.jsx:22), aucun skip link, aucun aria-live sur le compteur de résultats.
A34: =[1]Maître!$A$18 -> C2 | B34: =[1]Maître!$B$18 -> Qualité CSS | C34: =[1]Maître!$C$18 -> Flexbox / Grid, pas de tableaux HTML pour la mise en page, classes cohérentes. | D34: =[1]Maître!$D$18 -> 5 | E34: 3 | F34: Tailwind v4 @theme avec 3 tokens (mtl-primaire #15803D, mtl-survol #166534, mtl-actif #14532D), usage cohérent dans tous les composants. PROMPTS.md entrée 3 montre vérification WebAIM et modification manuelle du ratio. Mais seulement 3 tokens (nuances du même vert), aucun token pour texte/fond/surface, aucune documentation de contraste dans le code (index.css = 7 lignes, aucun commentaire ratio).
A35: =[1]Maître!$A$19 -> C3 | B35: =[1]Maître!$B$19 -> Qualité JS | C35: =[1]Maître!$C$19 -> Code lisible, fonctions courtes, gestion d'erreurs minimale présente. | D35: =[1]Maître!$D$19 -> 7 | E35: 6 | F35: PapaParse (justifié dans DEMARCHE D4) ✓, useCSV + useSort hooks génériques ✓, DataTable + PageLayout composants réutilisables (DRY/SOLID) ✓, point-in-polygon ray-casting (MultiPolygon) ✓, useMemo sur enrichissement+filtrage ✓, pagination avec reset au filtre ✓, toLocaleString('fr-CA') ✓. Lacunes : useCSV sans état error (Statistiques reste en 'chargement' si le fetch échoue), GeoJSON fetch dans Statistiques sans .catch (Statistiques.jsx:57-61), sort sans localeCompare('fr') (useSort.js:25-26).
A36: =[1]Maître!$A$20 -> C4 | B36: =[1]Maître!$B$20 -> Dépôt Git | C36: =[1]Maître!$C$20 -> Commits réguliers des trois membres, messages clairs, [IA] présent si applicable. | D36: =[1]Maître!$D$20 -> 5 | E36: 4 | F36: 8/17 commits marqués [IA] (cohérent avec les 7 entrées PROMPTS.md) ✓, 2 branches (omar, christian) + 2 PRs ✓, messages descriptifs ✓. Répartition : Omar 65%, Christian 35% — acceptable pour 2 membres, mais légèrement déséquilibré (5 entrées PROMPTS Omar, 2 Christian).
A37: =[1]Maître!$A$21 -> C5 | B37: =[1]Maître!$B$21 -> Journal de démarche | C37: =[1]Maître!$C$21 -> Parcours avec IA : PROMPTS.md à jour. Parcours sans IA : DEMARCHE.md à jour. | D37: =[1]Maître!$D$21 -> 10 | E37: 10 | F37: PROMPTS.md : 7 entrées liées aux commits, 2 auteurs (Christian entrées 1-2, Omar entrées 3-7), prompts réels inclus. Section hallucinations ✓ (colonne inventée, sur-ingénierie Tailwind). Entrée 1 : rejet quasi-total (code illisible, réécriture complète) — jugement critique honnête. Entrée 5 : hallucination détectée et corrigée (Ray-Casting). DEMARCHE : 4 décisions avec tableau d'alternatives + justification.
A38: Sous-total — code | D38: =[1]Maître!$D$22 -> 35 | E38: =SUM(E33:E37) -> 31
A40: =[1]Maître!$A$24 -> 3. Rapport — 40 points
A41: # | B41: Critère | C41: Description | D41: Max | E41: Note | F41: Commentaires
A42: =[1]Maître!$A$26 -> R1 | B42: =[1]Maître!$B$26 -> Architecture | C42: =[1]Maître!$C$26 -> Description claire, rôle des modules, justification du cadriciel. | D42: =[1]Maître!$D$26 -> 8 | E42: 6 | F42: React+Vite vs Vanilla JS vs CDN comparé et justifié (phases futures) ✓. Tableau fichier/rôle pour chaque module ✓. Tailwind justifié vs Bootstrap vs CSS pur (DEMARCHE D2). Limites : pas de description du flux de données (useCSV→useMemo→filtrage), pas de discussion sur la gestion d'erreurs, pas mention du routage React Router ni de la structure SPA.
A43: =[1]Maître!$A$27 -> R2 | B43: =[1]Maître!$B$27 -> Implémentation | C43: =[1]Maître!$C$27 -> Explication concise du tri, de la recherche et du filtrage. | D43: =[1]Maître!$D$27 -> 6 | E43: 4 | F43: Tri (useSort + useMemo, asc/desc, numérique/chaîne) bien décrit ✓. Recherche (useState + useMemo + filter/includes + toLowerCase) ✓. Ray-Casting (isPointInPolygon) expliqué clairement ✓. Réseau : le rapport décrit la formule haversine mais le code final utilise f.properties.LONGUEUR/1000 (haversine supprimée — PROMPTS.md entrée 2). Incohérence rapport/implémentation. Pagination non mentionnée.
A44: =[1]Maître!$A$28 -> R3 | B44: =[1]Maître!$B$28 -> Accessibilité et thème | C44: =[1]Maître!$C$28 -> Couleurs documentées, démarche d'accessibilité. | D44: =[1]Maître!$D$28 -> 6 | E44: 6 | F44: Tableau couleurs hex+ratio (3 lignes : #15803D 5,01:1, #F1F5F9 fond, #0F172A texte) ✓. HTML sémantique listé ✓. Responsive décrit (max-w-screen-xl, filtres+contenu, hamburger) ✓. Mais : revendique 'boutons de tri accessibles via Tab' — le tri est sur <th> onClick (DataTable.jsx:22), non accessible au clavier. Labels sans htmlFor non mentionnés. Aucune mention de skip link, aria-sort, aria-live, aria-expanded.
A45: =[1]Maître!$A$29 -> R4 | B45: =[1]Maître!$B$29 -> Démarche professionnelle et réflexion critique | C45: =[1]Maître!$C$29 -> Section dédiée du rapport rendant compte du parcours choisi. | D45: =[1]Maître!$D$29 -> 12 | E45: 10 | F45: 2 outils (Claude Sonnet 4.6 + Gemini Pro) avec rôles distincts justifiés ✓. Tâches déléguées listées ✓. Évolution des prompts : vagues→précis avec contraintes (retourner fichiers complets, interdire listes numérotées) ✓. Erreurs documentées : invention de colonne CSV, sur-ingénierie Tailwind ✓. Gain 50% estimé ✓. 4 mesures de maîtrise (explication, relecture, PROMPTS.md, 0 intégration sans relecture) ✓. Solide mais section brève ; aurrait gagné à détailler l'évolution par commit.
A46: =[1]Maître!$A$30 -> R5 | B46: =[1]Maître!$B$30 -> Répartition et présentation | C46: =[1]Maître!$C$30 -> Rôles précis, intro / conclusion soignées, qualité de la mise en page. | D46: =[1]Maître!$D$30 -> 8 | E46: 6 | F46: Tableau de répartition par membre avec contributions spécifiques (fichiers/hooks/fonctionnalités) ✓. Conclusion cite React, IA accélération + validation rigoureuse ✓. Déductions : pas de pourcentage de commits ni analyse Git, conclusion courte et générique, la stratégie de branchement n'est pas mentionnée.
...
